Workbook

Sheet Baseline 2025
A4: 97% Jet-A1 & 3% SAF
AC5: Crew costs | AI5: Costs | AO5: Revenue
B6: Destination | C6: Aircraft | D6: Fuel type | E6: Frequency [per year] | F6: # retour | G6: # flights | H6: Lookup: Distance [km] | I6: Total distance travelled [km] | J6: Lookup: Flight Type | K6: Lookup: fuel consumption [l/100km] | L6: Conditional: Total fuel consumption [l] | M6: SAF LFEC CO2 per kg [kg/kg] | N6: Total CO2 emmission [kg] (tons) | O6: NOX per KG | P6: Total NOX emmision(Tons) | Q6: Sox per KG | R6: Total Sox emmission(Ton) | S6: Seats | T6: Passengers per year | U6: Available cargo (Tons) | V6: Flight time | W6: Fuel | X6: jet-A1 Fuel | Y6: Jet-A1 price | Z6: SAF fuel | AA6: SAF price | AB6: Ticket price | AC6: Pilot | AD6: Cabin crew | AE6: Freight rate (Euro/KG) | AF6: Crew costs | AG6: Airport & Navigation charges | AH6: Maintenance costs | AI6: Maintenance reserve | AJ6: Operational lease | AK6: catering and inflight services | AL6: Insurance and overhead | AM6: Total costs | AN6: Passenger revenu | AO6: Cargo revenu | AP6: Total revenue
B7: 1 ALC | C7: Fokker 100 | D7: SAF | E7: =7*52*2 -> 728 | F7: =E7/2 -> 364 | G7: =E7 -> 728 | H7: =_xlfn.XLOOKUP(B7,'[1]Baseline 2025'!$B:$B,'[1]Baseline 2025'!$C:$C) -> 1613 | I7: =E7*H7 -> 1174264 | J7: =_xlfn.XLOOKUP(B7,'[1]Baseline 2025'!$B:$B,'[1]Baseline 2025'!$E:$E) -> Short Haul | K7: =_xlfn.XLOOKUP(B7,'[1]Baseline 2025'!$B:$B,'[1]Baseline 2025'!$I:$I)/100 -> 43095.489 | L7: =K7*100 -> 4309548.9 | M7: 3.84 | N7: =(L7*M7)/1000 -> 16548.668 | O7: =12/1000 -> 0.012 | P7: =(O7*L7)/1000 -> 51.714587 | Q7: =1.2/1000 -> 0.0012 | R7: =Q7*L7/1000 -> 5.1714587 | S7: 100 | T7: =G7*S7*assumptions!$D$6 -> 61880 | U7: 10.9 | V7: 0.11111111 | W7: 5919.71 | X7: =W7*0.97 -> 5742.1187 | Y7: =X7*assumptions!$C$7 -> 7464.7543 | Z7: =W7*0.03 -> 177.5913 | AA7: =Z7*assumptions!$C$8 -> 319.66434 | AB7: 172 | AC7: 2 | AD7: 3 | AE7: 3.5 | AF7: 1201.5 | AG7: 6845 | AH7: 21360 | AI7: 5340 | AJ7: 1669 | AK7: 2550 | AL7: 3341 | AM7: =Y7+AF7+AG7+AH7+AI7+AJ7+AK7+AL7+AA7 -> 50090.919 | AN7: 14620 | AO7: 38150 | AP7: =AN7+AO7 -> 52770
B8: 2 ARN | C8: Fokker 100 | D8: SAF | E8: =7*52*2 -> 728 | F8: =E8/2 -> 364 | G8: =E8 -> 728 | H8: =_xlfn.XLOOKUP(B8,'[1]Baseline 2025'!$B:$B,'[1]Baseline 2025'!$C:$C) -> 1155 | I8: =E8*H8 -> 840840 | J8: =_xlfn.XLOOKUP(B8,'[1]Baseline 2025'!$B:$B,'[1]Baseline 2025'!$E:$E) -> Short Haul | K8: =_xlfn.XLOOKUP(B8,'[1]Baseline 2025'!$B:$B,'[1]Baseline 2025'!$I:$I)/100 -> 30858.828 | L8: =K8*100 -> 3085882.8 | M8: 3.84 | N8: =(L8*M8)/1000 -> 11849.79 | O8: =12/1000 -> 0.012 | P8: =(O8*L8)/1000 -> 37.030594 | Q8: =1.2/1000 -> 0.0012 | R8: =Q8*L8/1000 -> 3.7030594 | S8: 100 | T8: =G8*S8*assumptions!$D$6 -> 61880 | U8: 10.9 | V8: 0.083333333 | W8: 4238.85 | X8: =W8*0.97 -> 4111.6845 | Y8: =X8*assumptions!$C$7 -> 5345.1899 | Z8: =W8*0.03 -> 127.1655 | AA8: =Z8*assumptions!$C$8 -> 228.8979 | AB8: 99 | AC8: 2 | AD8: 3 | AE8: 3 | AF8: 900 | AG8: 6158 | AH8: 16000 | AI8: 4000 | AJ8: 1250 | AK8: 2550 | AL8: 2603 | AM8: =Y8+AF8+AG8+AH8+AI8+AJ8+AK8+AL8+AA8 -> 39035.088 | AN8: 8415 | AO8: 32700 | AP8: =AN8+AO8 -> 41115
B9: 3 BCN | C9: Fokker 100 | D9: SAF | E9: =7*52*2 -> 728 | F9: =E9/2 -> 364 | G9: =E9 -> 728 | H9: =_xlfn.XLOOKUP(B9,'[1]Baseline 2025'!$B:$B,'[1]Baseline 2025'!$C:$C) -> 1241 | I9: =E9*H9 -> 903448 | J9: =_xlfn.XLOOKUP(B9,'[1]Baseline 2025'!$B:$B,'[1]Baseline 2025'!$E:$E) -> Short Haul | K9: =_xlfn.XLOOKUP(B9,'[1]Baseline 2025'!$B:$B,'[1]Baseline 2025'!$I:$I)/100 -> 33156.542 | L9: =K9*100 -> 3315654.2 | M9: 3.84 | N9: =(L9*M9)/1000 -> 12732.112 | O9: =12/1000 -> 0.012 | P9: =(O9*L9)/1000 -> 39.78785 | Q9: =1.2/1000 -> 0.0012 | R9: =Q9*L9/1000 -> 3.978785 | S9: 100 | T9: =G9*S9*assumptions!$D$6 -> 61880 | U9: 10.9 | V9: 0.097222222 | W9: 4554.47 | X9: =W9*0.97 -> 4417.8359 | Y9: =X9*assumptions!$C$7 -> 5743.1867 | Z9: =W9*0.03 -> 136.6341 | AA9: =Z9*assumptions!$C$8 -> 245.94138 | AB9: 90 | AC9: 2 | AD9: 3 | AE9: 3.5 | AF9: 1048.5 | AG9: 6287 | AH9: 18640 | AI9: 4660 | AJ9: 1456 | AK9: 2550 | AL9: 2903 | AM9: =Y9+AF9+AG9+AH9+AI9+AJ9+AK9+AL9+AA9 -> 43533.628 | AN9: 7650 | AO9: 38150 | AP9: =AN9+AO9 -> 45800
B10: 4 BRU | C10: Fokker 100 | D10: SAF | E10: =14*52 -> 728 | F10: =E10/2 -> 364 | G10: =E10 -> 728 | H10: =_xlfn.XLOOKUP(B10,'[1]Baseline 2025'!$B:$B,'[1]Baseline 2025'!$C:$C) -> 158 | I10: =E10*H10 -> 115024 | J10: =_xlfn.XLOOKUP(B10,'[1]Baseline 2025'!$B:$B,'[1]Baseline 2025'!$E:$E) -> Short Haul | K10: =_xlfn.XLOOKUP(B10,'[1]Baseline 2025'!$B:$B,'[1]Baseline 2025'!$I:$I)/100 -> 8442.7616 | L10: =K10*100 -> 844276.16 | M10: 3.84 | N10: =(L10*M10)/1000 -> 3242.0205 | O10: =12/1000 -> 0.012 | P10: =(O10*L10)/1000 -> 10.131314 | Q10: =1.2/1000 -> 0.0012 | R10: =Q10*L10/1000 -> 1.0131314 | S10: 100 | T10: =G10*S10*assumptions!$D$6 -> 61880 | U10: 10.9 | V10: 0.027777778 | W10: 579.86 | X10: =W10*0.97 -> 562.4642 | Y10: =X10*assumptions!$C$7 -> 731.20346 | Z10: =W10*0.03 -> 17.3958 | AA10: =Z10*assumptions!$C$8 -> 31.31244 | AB10: 37.5 | AC10: 2 | AD10: 3 | AE10: 3.5 | AF10: 300.015 | AG10: 4662 | AH10: 5333.6 | AI10: 1333.4 | AJ10: 417 | AK10: 2550 | AL10: 1097 | AM10: =Y10+AF10+AG10+AH10+AI10+AJ10+AK10+AL10+AA10 -> 16455.531 | AN10: 3187.5 | AO10: 38150 | AP10: =AN10+AO10 -> 41337.5
B11: 5 BSL | C11: Fokker 100 | D11: SAF | E11: =7*52*2 -> 728 | F11: =E11/2 -> 364 | G11: =E11 -> 728 | H11: =_xlfn.XLOOKUP(B11,'[1]Baseline 2025'!$B:$B,'[1]Baseline 2025'!$C:$C) -> 561 | I11: =E11*H11 -> 408408 | J11: =_xlfn.XLOOKUP(B11,'[1]Baseline 2025'!$B:$B,'[1]Baseline 2025'!$E:$E) -> Short Haul | K11: =_xlfn.XLOOKUP(B11,'[1]Baseline 2025'!$B:$B,'[1]Baseline 2025'!$I:$I)/100 -> 14988.574 | L11: =K11*100 -> 1498857.4 | M11: 3.84 | N11: =(L11*M11)/1000 -> 5755.6123 | O11: =12/1000 -> 0.012 | P11: =(O11*L11)/1000 -> 17.986288 | Q11: =1.2/1000 -> 0.0012 | R11: =Q11*L11/1000 -> 1.7986288 | S11: 100 | T11: =G11*S11*assumptions!$D$6 -> 61880 | U11: 10.9 | V11: 0.055555556 | W11: 2058.87 | X11: =W11*0.97 -> 1997.1039 | Y11: =X11*assumptions!$C$7 -> 2596.2351 | Z11: =W11*0.03 -> 61.7661 | AA11: =Z11*assumptions!$C$8 -> 111.17898 | AB11: 45 | AC11: 2 | AD11: 3 | AE11: 3.5 | AF11: 598.5 | AG11: 5267 | AH11: 10640 | AI11: 2660 | AJ11: 831 | AK11: 2550 | AL11: 1805 | AM11: =Y11+AF11+AG11+AH11+AI11+AJ11+AK11+AL11+AA11 -> 27058.914 | AN11: 3825 | AO11: 38150 | AP11: =AN11+AO11 -> 41975
B12: 6 CDG | C12: Fokker 100 | D12: SAF | E12: =7*52 -> 364 | F12: =E12/2 -> 182 | G12: =E12 -> 364 | H12: =_xlfn.XLOOKUP(B12,'[1]Baseline 2025'!$B:$B,'[1]Baseline 2025'!$C:$C) -> 399 | I12: =E12*H12 -> 145236 | J12: =_xlfn.XLOOKUP(B12,'[1]Baseline 2025'!$B:$B,'[1]Baseline 2025'!$E:$E) -> Short Haul | K12: =_xlfn.XLOOKUP(B12,'[1]Baseline 2025'!$B:$B,'[1]Baseline 2025'!$I:$I)/100 -> 10660.322 | L12: =K12*100 -> 1066032.2 | M12: 3.84 | N12: =(L12*M12)/1000 -> 4093.5638 | O12: =12/1000 -> 0.012 | P12: =(O12*L12)/1000 -> 12.792387 | Q12: =1.2/1000 -> 0.0012 | R12: =Q12*L12/1000 -> 1.2792387 | S12: 100 | T12: =G12*S12*assumptions!$D$6 -> 30940 | U12: 10.9 | V12: 0.055555556 | W12: 1464.33 | X12: =W12*0.97 -> 1420.4001 | Y12: =X12*assumptions!$C$7 -> 1846.5201 | Z12: =W12*0.03 -> 43.9299 | AA12: =Z12*assumptions!$C$8 -> 79.07382 | AB12: 30 | AC12: 2 | AD12: 3 | AE12: 3.5 | AF12: 598.5 | AG12: 5024 | AH12: 10640 | AI12: 2660 | AJ12: 831 | AK12: 2550 | AL12: 1811 | AM12: =Y12+AF12+AG12+AH12+AI12+AJ12+AK12+AL12+AA12 -> 26040.094 | AN12: 2550 | AO12: 38150 | AP12: =AN12+AO12 -> 40700
B13: 7 DUB | C13: Fokker 100 | D13: SAF | E13: =7*52 -> 364 | F13: =E13/2 -> 182 | G13: =E13 -> 364 | H13: =_xlfn.XLOOKUP(B13,'[1]Baseline 2025'!$B:$B,'[1]Baseline 2025'!$C:$C) -> 753 | I13: =E13*H13 -> 274092 | J13: =_xlfn.XLOOKUP(B13,'[1]Baseline 2025'!$B:$B,'[1]Baseline 2025'!$E:$E) -> Short Haul | K13: =_xlfn.XLOOKUP(B13,'[1]Baseline 2025'!$B:$B,'[1]Baseline 2025'!$I:$I)/100 -> 20118.353 | L13: =K13*100 -> 2011835.3 | M13: 3.84 | N13: =(L13*M13)/1000 -> 7725.4475 | O13: =12/1000 -> 0.012 | P13: =(O13*L13)/1000 -> 24.142023 | Q13: =1.2/1000 -> 0.0012 | R13: =Q13*L13/1000 -> 2.4142023 | S13: 100 | T13: =G13*S13*assumptions!$D$6 -> 30940 | U13: 10.9 | V13: 0.069444444 | W13: 2763.51 | X13: =W13*0.97 -> 2680.6047 | Y13: =X13*assumptions!$C$7 -> 3484.7861 | Z13: =W13*0.03 -> 82.9053 | AA13: =Z13*assumptions!$C$8 -> 149.22954 | AB13: 75 | AC13: 2 | AD13: 3 | AE13: 3.5 | AF13: 747 | AG13: 5555 | AH13: 13280 | AI13: 3320 | AJ13: 1038 | AK13: 2550 | AL13: 2273 | AM13: =Y13+AF13+AG13+AH13+AI13+AJ13+AK13+AL13+AA13 -> 32397.016 | AN13: 6375 | AO13: 38150 | AP13: =AN13+AO13 -> 44525
B14: 8 FAO | C14: Fokker 100 | D14: SAF | E14: =7*52 -> 364 | F14: =E14/2 -> 182 | G14: =E14 -> 364 | H14: =_xlfn.XLOOKUP(B14,'[1]Baseline 2025'!$B:$B,'[1]Baseline 2025'!$C:$C) -> 1970 | I14: =E14*H14 -> 717080 | J14: =_xlfn.XLOOKUP(B14,'[1]Baseline 2025'!$B:$B,'[1]Baseline 2025'!$E:$E) -> Short Haul | K14: =_xlfn.XLOOKUP(B14,'[1]Baseline 2025'!$B:$B,'[1]Baseline 2025'!$I:$I)/100 -> 52633.672 | L14: =K14*100 -> 5263367.2 | M14: 3.84 | N14: =(L14*M14)/1000 -> 20211.33 | O14: =12/1000 -> 0.012 | P14: =(O14*L14)/1000 -> 63.160406 | Q14: =1.2/1000 -> 0.0012 | R14: =Q14*L14/1000 -> 6.3160406 | S14: 100 | T14: =G14*S14*assumptions!$D$6 -> 30940 | U14: 10.9 | V14: 0.125 | W14: 7229.9 | X14: =W14*0.97 -> 7013.003 | Y14: =X14*assumptions!$C$7 -> 9116.9039 | Z14: =W14*0.03 -> 216.897 | AA14: =Z14*assumptions!$C$8 -> 390.4146 | AB14: 250 | AC14: 2 | AD14: 3 | AE14: 3.5 | AF14: 1350 | AG14: 7380 | AH14: 24000 | AI14: 6000 | AJ14: 1875 | AK14: 2550 | AL14: 3763 | AM14: =Y14+AF14+AG14+AH14+AI14+AJ14+AK14+AL14+AA14 -> 56425.318 | AN14: 21250 | AO14: 38150 | AP14: =AN14+AO14 -> 59400
B15: 9 LIS | C15: Fokker 100 | D15: SAF | E15: =7*52 -> 364 | F15: =E15/2 -> 182 | G15: =E15 -> 364 | H15: =_xlfn.XLOOKUP(B15,'[1]Baseline 2025'!$B:$B,'[1]Baseline 2025'!$C:$C) -> 1848 | I15: =E15*H15 -> 672672 | J15: =_xlfn.XLOOKUP(B15,'[1]Baseline 2025'!$B:$B,'[1]Baseline 2025'!$E:$E) -> Short Haul | K15: =_xlfn.XLOOKUP(B15,'[1]Baseline 2025'!$B:$B,'[1]Baseline 2025'!$I:$I)/100 -> 49374.125 | L15: =K15*100 -> 4937412.5 | M15: 3.84 | N15: =(L15*M15)/1000 -> 18959.664 | O15: =12/1000 -> 0.012 | P15: =(O15*L15)/1000 -> 59.24895 | Q15: =1.2/1000 -> 0.0012 | R15: =Q15*L15/1000 -> 5.924895 | S15: 100 | T15: =G15*S15*assumptions!$D$6 -> 30940 | U15: 10.9 | V15: 0.13194444 | W15: 6782.16 | X15: =W15*0.97 -> 6578.6952 | Y15: =X15*assumptions!$C$7 -> 8552.3038 | Z15: =W15*0.03 -> 203.4648 | AA15: =Z15*assumptions!$C$8 -> 366.23664 | AB15: 264 | AC15: 2 | AD15: 3 | AE15: 3.5 | AF15: 1425.015 | AG15: 7197 | AH15: 25333.6 | AI15: 6333.4 | AJ15: 1979 | AK15: 2550 | AL15: 3840 | AM15: =Y15+AF15+AG15+AH15+AI15+AJ15+AK15+AL15+AA15 -> 57576.555 | AN15: 22440 | AO15: 38150 | AP15: =AN15+AO15 -> 60590
B16: 10 MUC | C16: Fokker 100 | D16: SAF | E16: =7*52 -> 364 | F16: =E16/2 -> 182 | G16: =E16 -> 364 | H16: =_xlfn.XLOOKUP(B16,'[1]Baseline 2025'!$B:$B,'[1]Baseline 2025'!$C:$C) -> 665 | I16: =E16*H16 -> 242060 | J16: =_xlfn.XLOOKUP(B16,'[1]Baseline 2025'!$B:$B,'[1]Baseline 2025'!$E:$E) -> Short Haul | K16: =_xlfn.XLOOKUP(B16,'[1]Baseline 2025'!$B:$B,'[1]Baseline 2025'!$I:$I)/100 -> 17767.204 | L16: =K16*100 -> 1776720.4 | M16: 3.84 | N16: =(L16*M16)/1000 -> 6822.6063 | O16: =12/1000 -> 0.012 | P16: =(O16*L16)/1000 -> 21.320645 | Q16: =1.2/1000 -> 0.0012 | R16: =Q16*L16/1000 -> 2.1320645 | S16: 100 | T16: =G16*S16*assumptions!$D$6 -> 30940 | U16: 10.9 | V16: 0.059027778 | W16: 2440.55 | X16: =W16*0.97 -> 2367.3335 | Y16: =X16*assumptions!$C$7 -> 3077.5335 | Z16: =W16*0.03 -> 73.2165 | AA16: =Z16*assumptions!$C$8 -> 131.7897 | AB16: 49 | AC16: 2 | AD16: 3 | AE16: 3.5 | AF16: 639 | AG16: 5423 | AH16: 11360 | AI16: 2840 | AJ16: 888 | AK16: 2550 | AL16: 1923 | AM16: =Y16+AF16+AG16+AH16+AI16+AJ16+AK16+AL16+AA16 -> 28832.323 | AN16: 4143.75 | AO16: 38150 | AP16: =AN16+AO16 -> 42293.75
B17: 11 OSL | C17: Fokker 100 | D17: SAF | E17: =7*52 -> 364 | F17: =E17/2 -> 182 | G17: =E17 -> 364 | H17: =_xlfn.XLOOKUP(B17,'[1]Baseline 2025'!$B:$B,'[1]Baseline 2025'!$C:$C) -> 961 | I17: =E17*H17 -> 349804 | J17: =_xlfn.XLOOKUP(B17,'[1]Baseline 2025'!$B:$B,'[1]Baseline 2025'!$E:$E) -> Short Haul | K17: =_xlfn.XLOOKUP(B17,'[1]Baseline 2025'!$B:$B,'[1]Baseline 2025'!$I:$I)/100 -> 25675.614 | L17: =K17*100 -> 2567561.4 | M17: 3.84 | N17: =(L17*M17)/1000 -> 9859.4356 | O17: =12/1000 -> 0.012 | P17: =(O17*L17)/1000 -> 30.810736 | Q17: =1.2/1000 -> 0.0012 | R17: =Q17*L17/1000 -> 3.0810736 | S17: 100 | T17: =G17*S17*assumptions!$D$6 -> 30940 | U17: 10.9 | V17: 0.072916667 | W17: 3526.87 | X17: =W17*0.97 -> 3421.0639 | Y17: =X17*assumptions!$C$7 -> 4447.3831 | Z17: =W17*0.03 -> 105.8061 | AA17: =Z17*assumptions!$C$8 -> 190.45098 | AB17: 52.5 | AC17: 2 | AD17: 3 | AE17: 3.5 | AF17: 787.5 | AG17: 5867 | AH17: 14000 | AI17: 3500 | AJ17: 1094 | AK17: 2550 | AL17: 2318 | AM17: =Y17+AF17+AG17+AH17+AI17+AJ17+AK17+AL17+AA17 -> 34754.334 | AN17: 4462.5 | AO17: 38150 | AP17: =AN17+AO17 -> 42612.5
B18: 12 PMI | C18: Fokker 100 | D18: SAF | E18: =7*52 -> 364 | F18: =E18/2 -> 182 | G18: =E18 -> 364 | H18: =_xlfn.XLOOKUP(B18,'[1]Baseline 2025'!$B:$B,'[1]Baseline 2025'!$C:$C) -> 1426 | I18: =E18*H18 -> 519064 | J18: =_xlfn.XLOOKUP(B18,'[1]Baseline 2025'!$B:$B,'[1]Baseline 2025'!$E:$E) -> Short Haul | K18: =_xlfn.XLOOKUP(B18,'[1]Baseline 2025'!$B:$B,'[1]Baseline 2025'!$I:$I)/100 -> 38099.298 | L18: =K18*100 -> 3809929.8 | M18: 3.84 | N18: =(L18*M18)/1000 -> 14630.13 | O18: =12/1000 -> 0.012 | P18: =(O18*L18)/1000 -> 45.719157 | Q18: =1.2/1000 -> 0.0012 | R18: =Q18*L18/1000 -> 4.5719157 | S18: 100 | T18: =G18*S18*assumptions!$D$6 -> 30940 | U18: 10.9 | V18: 0.10069444 | W18: 5233.42 | X18: =W18*0.97 -> 5076.4174 | Y18: =X18*assumptions!$C$7 -> 6599.3426 | Z18: =W18*0.03 -> 157.0026 | AA18: =Z18*assumptions!$C$8 -> 282.60468 | AB18: 128 | AC18: 2 | AD18: 3 | AE18: 3.5 | AF18: 1089 | AG18: 6564 | AH18: 19360 | AI18: 4840 | AJ18: 1513 | AK18: 2550 | AL18: 3058 | AM18: =Y18+AF18+AG18+AH18+AI18+AJ18+AK18+AL18+AA18 -> 45855.947 | AN18: 10837.5 | AO18: 38150 | AP18: =AN18+AO18 -> 48987.5
B19: 13 VIE | C19: Fokker 100 | D19: SAF | E19: =7*52 -> 364 | F19: =E19/2 -> 182 | G19: =E19 -> 364 | H19: =_xlfn.XLOOKUP(B19,'[1]Baseline 2025'!$B:$B,'[1]Baseline 2025'!$C:$C) -> 962 | I19: =E19*H19 -> 350168 | J19: =_xlfn.XLOOKUP(B19,'[1]Baseline 2025'!$B:$B,'[1]Baseline 2025'!$E:$E) -> Short Haul | K19: =_xlfn.XLOOKUP(B19,'[1]Baseline 2025'!$B:$B,'[1]Baseline 2025'!$I:$I)/100 -> 25702.331 | L19: =K19*100 -> 2570233.1 | M19: 3.84 | N19: =(L19*M19)/1000 -> 9869.6952 | O19: =12/1000 -> 0.012 | P19: =(O19*L19)/1000 -> 30.842797 | Q19: =1.2/1000 -> 0.0012 | R19: =Q19*L19/1000 -> 3.0842797 | S19: 100 | T19: =G19*S19*assumptions!$D$6 -> 30940 | U19: 10.9 | V19: 0.072916667 | W19: 3530.54 | X19: =W19*0.97 -> 3424.6238 | Y19: =X19*assumptions!$C$7 -> 4452.0109 | Z19: =W19*0.03 -> 105.9162 | AA19: =Z19*assumptions!$C$8 -> 190.64916 | AB19: 60.75 | AC19: 2 | AD19: 3 | AE19: 3.5 | AF19: 787.5 | AG19: 5868 | AH19: 14000 | AI19: 3500 | AJ19: 1094 | AK19: 2550 | AL19: 2318 | AM19: =Y19+AF19+AG19+AH19+AI19+AJ19+AK19+AL19+AA19 -> 34760.16 | AN19: 5163.75 | AO19: 38150 | AP19: =AN19+AO19 -> 43313.75
B20: 14 WAW | C20: Fokker 100 | D20: SAF | E20: =7*52 -> 364 | F20: =E20/2 -> 182 | G20: =E20 -> 364 | H20: =_xlfn.XLOOKUP(B20,'[1]Baseline 2025'!$B:$B,'[1]Baseline 2025'!$C:$C) -> 1105 | I20: =E20*H20 -> 402220 | J20: =_xlfn.XLOOKUP(B20,'[1]Baseline 2025'!$B:$B,'[1]Baseline 2025'!$E:$E) -> Short Haul | K20: =_xlfn.XLOOKUP(B20,'[1]Baseline 2025'!$B:$B,'[1]Baseline 2025'!$I:$I)/100 -> 29522.948 | L20: =K20*100 -> 2952294.8 | M20: 3.84 | N20: =(L20*M20)/1000 -> 11336.812 | O20: =12/1000 -> 0.012 | P20: =(O20*L20)/1000 -> 35.427538 | Q20: =1.2/1000 -> 0.0012 | R20: =Q20*L20/1000 -> 3.5427538 | S20: 100 | T20: =G20*S20*assumptions!$D$6 -> 30940 | U20: 10.9 | V20: 0.079861111 | W20: 4055.35 | X20: =W20*0.97 -> 3933.6895 | Y20: =X20*assumptions!$C$7 -> 5113.7964 | Z20: =W20*0.03 -> 121.6605 | AA20: =Z20*assumptions!$C$8 -> 218.9889 | AB20: 66 | AC20: 2 | AD20: 3 | AE20: 3.5 | AF20: 862.515 | AG20: 6083 | AH20: 15333.6 | AI20: 3833.4 | AJ20: 1198 | AK20: 2550 | AL20: 2515 | AM20: =Y20+AF20+AG20+AH20+AI20+AJ20+AK20+AL20+AA20 -> 37708.3 | AN20: 5610 | AO20: 38150 | AP20: =AN20+AO20 -> 43760
B21: 15 ZRH | C21: Fokker 100 | D21: SAF | E21: =14*52*2 -> 1456 | F21: =E21/2 -> 728 | G21: =E21 -> 1456 | H21: =_xlfn.XLOOKUP(B21,'[1]Baseline 2025'!$B:$B,'[1]Baseline 2025'!$C:$C) -> 603 | I21: =E21*H21 -> 877968 | J21: =_xlfn.XLOOKUP(B21,'[1]Baseline 2025'!$B:$B,'[1]Baseline 2025'!$E:$E) -> Short Haul | K21: =_xlfn.XLOOKUP(B21,'[1]Baseline 2025'!$B:$B,'[1]Baseline 2025'!$I:$I)/100 -> 32221.426 | L21: =K21*100 -> 3222142.6 | M21: 3.84 | N21: =(L21*M21)/1000 -> 12373.027 | O21: =12/1000 -> 0.012 | P21: =(O21*L21)/1000 -> 38.665711 | Q21: =1.2/1000 -> 0.0012 | R21: =Q21*L21/1000 -> 3.8665711 | S21: 100 | T21: =G21*S21*assumptions!$D$6 -> 123760 | U21: 10.9 | V21: 0.059027778 | W21: 2213.01 | X21: =W21*0.97 -> 2146.6197 | Y21: =X21*assumptions!$C$7 -> 2790.6056 | Z21: =W21*0.03 -> 66.3903 | AA21: =Z21*assumptions!$C$8 -> 119.50254 | AB21: 48.75 | AC21: 2 | AD21: 3 | AE21: 3.5 | AF21: 637.515 | AG21: 5330 | AH21: 11333.6 | AI21: 2833.4 | AJ21: 885 | AK21: 2550 | AL21: 1892 | AM21: =Y21+AF21+AG21+AH21+AI21+AJ21+AK21+AL21+AA21 -> 28371.623 | AN21: 4143.75 | AO21: 38150 | AP21: =AN21+AO21 -> 42293.75
B22: 16 BKK | C22: B777-200er | D22: SAF | E22: =3*52*2 -> 312 | F22: =E22/2 -> 156 | G22: =E22 -> 312 | H22: =_xlfn.XLOOKUP(B22,'[1]Baseline 2025'!$B:$B,'[1]Baseline 2025'!$C:$C) -> 9217 | I22: =E22*H22 -> 2875704 | J22: =_xlfn.XLOOKUP(B22,'[1]Baseline 2025'!$B:$B,'[1]Baseline 2025'!$E:$E) -> Long Haul | K22: =_xlfn.XLOOKUP(B22,'[1]Baseline 2025'!$B:$B,'[1]Baseline 2025'!$I:$I)/100 -> 213377.24 | L22: =K22*100 -> 21337724 | M22: 3.84 | N22: =(L22*M22)/1000 -> 81936.859 | O22: =12/1000 -> 0.012 | P22: =(O22*L22)/1000 -> 256.05268 | Q22: =1.2/1000 -> 0.0012 | R22: =Q22*L22/1000 -> 25.605268 | S22: 300 | T22: =G22*S22*assumptions!$D$6 -> 79560 | U22: 20 | V22: 0.46875 | W22: 68390.14 | X22: =W22*0.97 -> 66338.436 | Y22: =X22*assumptions!$C$7 -> 86239.967 | Z22: =W22*0.03 -> 2051.7042 | AA22: =Z22*assumptions!$C$8 -> 3693.0676 | AB22: 920 | AC22: 3 | AD22: 12 | AE22: 3.5 | AF22: 11812.5 | AG22: 27101 | AH22: 90000 | AI22: 22500 | AJ22: 21094 | AK22: 7650 | AL22: 19300 | AM22: =Y22+AF22+AG22+AH22+AI22+AJ22+AK22+AL22+AA22 -> 289390.53 | AN22: 234600 | AO22: 70000 | AP22: =AN22+AO22 -> 304600
B23: 17 MFM | C23: B777-200er | D23: SAF | E23: =3*52*2 -> 312 | F23: =E23/2 -> 156 | G23: =E23 -> 312 | H23: =_xlfn.XLOOKUP(B23,'[1]Baseline 2025'!$B:$B,'[1]Baseline 2025'!$C:$C) -> 9285 | I23: =E23*H23 -> 2896920 | J23: =_xlfn.XLOOKUP(B23,'[1]Baseline 2025'!$B:$B,'[1]Baseline 2025'!$E:$E) -> Long Haul | K23: =_xlfn.XLOOKUP(B23,'[1]Baseline 2025'!$B:$B,'[1]Baseline 2025'!$I:$I)/100 -> 214951.46 | L23: =K23*100 -> 21495146 | M23: 3.84 | N23: =(L23*M23)/1000 -> 82541.362 | O23: =12/1000 -> 0.012 | P23: =(O23*L23)/1000 -> 257.94176 | Q23: =1.2/1000 -> 0.0012 | R23: =Q23*L23/1000 -> 25.794176 | S23: 300 | T23: =G23*S23*assumptions!$D$6 -> 79560 | U23: 20 | V23: 0.46875 | W23: 68894.7 | X23: =W23*0.97 -> 66827.859 | Y23: =X23*assumptions!$C$7 -> 86876.217 | Z23: =W23*0.03 -> 2066.841 | AA23: =Z23*assumptions!$C$8 -> 3720.3138 | AB23: 924 | AC23: 3 | AD23: 12 | AE23: 3.5 | AF23: 11812.5 | AG23: 27203 | AH23: 90000 | AI23: 22500 | AJ23: 21094 | AK23: 7650 | AL23: 19354 | AM23: =Y23+AF23+AG23+AH23+AI23+AJ23+AK23+AL23+AA23 -> 290210.03 | AN23: 235620 | AO23: 70000 | AP23: =AN23+AO23 -> 305620
B24: 18 HAN | C24: B777-200er | D24: SAF | E24: =52*2 -> 104 | F24: =E24/2 -> 52 | G24: =E24 -> 104 | H24: =_xlfn.XLOOKUP(B24,'[1]Baseline 2025'!$B:$B,'[1]Baseline 2025'!$C:$C) -> 8886 | I24: =E24*H24 -> 924144 | J24: =_xlfn.XLOOKUP(B24,'[1]Baseline 2025'!$B:$B,'[1]Baseline 2025'!$E:$E) -> Long Haul | K24: =_xlfn.XLOOKUP(B24,'[1]Baseline 2025'!$B:$B,'[1]Baseline 2025'!$I:$I)/100 -> 68571.485 | L24: =K24*100 -> 6857148.5 | M24: 3.84 | N24: =(L24*M24)/1000 -> 26331.45 | O24: =12/1000 -> 0.012 | P24: =(O24*L24)/1000 -> 82.285782 | Q24: =1.2/1000 -> 0.0012 | R24: =Q24*L24/1000 -> 8.2285782 | S24: 300 | T24: =G24*S24*assumptions!$D$6 -> 26520 | U24: 20 | V24: 0.45833333 | W24: 65934.12 | X24: =W24*0.97 -> 63956.096 | Y24: =X24*assumptions!$C$7 -> 83142.925 | Z24: =W24*0.03 -> 1978.0236 | AA24: =Z24*assumptions!$C$8 -> 3560.4425 | AB24: 889 | AC24: 3 | AD24: 12 | AE24: 3.5 | AF24: 11550 | AG24: 26604 | AH24: 88000 | AI24: 22000 | AJ24: 20625 | AK24: 7650 | AL24: 18802 | AM24: =Y24+AF24+AG24+AH24+AI24+AJ24+AK24+AL24+AA24 -> 281934.37 | AN24: 226695 | AO24: 70000 | AP24: =AN24+AO24 -> 296695
B25: 19 PTY | C25: B777-200er | D25: SAF | E25: =156*2 -> 312 | F25: =E25/2 -> 156 | G25: =E25 -> 312 | H25: =_xlfn.XLOOKUP(B25,'[1]Baseline 2025'!$B:$B,'[1]Baseline 2025'!$C:$C) -> 8818 | I25: =E25*H25 -> 2751216 | J25: =_xlfn.XLOOKUP(B25,'[1]Baseline 2025'!$B:$B,'[1]Baseline 2025'!$E:$E) -> Long Haul | K25: =_xlfn.XLOOKUP(B25,'[1]Baseline 2025'!$B:$B,'[1]Baseline 2025'!$I:$I)/100 -> 204140.23 | L25: =K25*100 -> 20414023 | M25: 3.84 | N25: =(L25*M25)/1000 -> 78389.847 | O25: =12/1000 -> 0.012 | P25: =(O25*L25)/1000 -> 244.96827 | Q25: =1.2/1000 -> 0.0012 | R25: =Q25*L25/1000 -> 24.496827 | S25: 300 | T25: =G25*S25*assumptions!$D$6 -> 79560 | U25: 20 | V25: 0.46527778 | W25: 65429.56 | X25: =W25*0.97 -> 63466.673 | Y25: =X25*assumptions!$C$7 -> 82506.675 | Z25: =W25*0.03 -> 1962.8868 | AA25: =Z25*assumptions!$C$8 -> 3533.1962 | AB25: 896 | AC25: 3 | AD25: 12 | AE25: 3.5 | AF25: 11718 | AG25: 26502 | AH25: 89280 | AI25: 22320 | AJ25: 20925 | AK25: 7650 | AL25: 18895 | AM25: =Y25+AF25+AG25+AH25+AI25+AJ25+AK25+AL25+AA25 -> 283329.87 | AN25: 228480 | AO25: 70000 | AP25: =AN25+AO25 -> 298480
B26: 20 MEX | C26: B777-200er | D26: SAF | E26: =156*2 -> 312 | F26: =E26/2 -> 156 | G26: =E26 -> 312 | H26: =_xlfn.XLOOKUP(B26,'[1]Baseline 2025'!$B:$B,'[1]Baseline 2025'!$C:$C) -> 9220 | I26: =E26*H26 -> 2876640 | J26: =_xlfn.XLOOKUP(B26,'[1]Baseline 2025'!$B:$B,'[1]Baseline 2025'!$E:$E) -> Long Haul | K26: =_xlfn.XLOOKUP(B26,'[1]Baseline 2025'!$B:$B,'[1]Baseline 2025'!$I:$I)/100 -> 213446.69 | L26: =K26*100 -> 21344669 | M26: 3.84 | N26: =(L26*M26)/1000 -> 81963.528 | O26: =12/1000 -> 0.012 | P26: =(O26*L26)/1000 -> 256.13603 | Q26: =1.2/1000 -> 0.0012 | R26: =Q26*L26/1000 -> 25.613603 | S26: 300 | T26: =G26*S26*assumptions!$D$6 -> 79560 | U26: 20 | V26: 0.47916667 | W26: 68412.4 | X26: =W26*0.97 -> 66360.028 | Y26: =X26*assumptions!$C$7 -> 86268.036 | Z26: =W26*0.03 -> 2052.372 | AA26: =Z26*assumptions!$C$8 -> 3694.2696 | AB26: 935 | AC26: 3 | AD26: 12 | AE26: 3.5 | AF26: 12075 | AG26: 27105 | AH26: 92000 | AI26: 23000 | AJ26: 21563 | AK26: 7650 | AL26: 19533 | AM26: =Y26+AF26+AG26+AH26+AI26+AJ26+AK26+AL26+AA26 -> 292888.31 | AN26: 238425 | AO26: 70000 | AP26: =AN26+AO26 -> 308425
B27: 21 GIG | C27: B777-200er | D27: SAF | E27: =52*2 -> 104 | F27: =E27/2 -> 52 | G27: =E27 -> 104 | H27: =_xlfn.XLOOKUP(B27,'[1]Baseline 2025'!$B:$B,'[1]Baseline 2025'!$C:$C) -> 9536 | I27: =E27*H27 -> 991744 | J27: =_xlfn.XLOOKUP(B27,'[1]Baseline 2025'!$B:$B,'[1]Baseline 2025'!$E:$E) -> Long Haul | K27: =_xlfn.XLOOKUP(B27,'[1]Baseline 2025'!$B:$B,'[1]Baseline 2025'!$I:$I)/100 -> 73587.405 | L27: =K27*100 -> 7358740.5 | M27: 3.84 | N27: =(L27*M27)/1000 -> 28257.563 | O27: =12/1000 -> 0.012 | P27: =(O27*L27)/1000 -> 88.304886 | Q27: =1.2/1000 -> 0.0012 | R27: =Q27*L27/1000 -> 8.8304886 | S27: 300 | T27: =G27*S27*assumptions!$D$6 -> 26520 | U27: 20 | V27: 0.5 | W27: 70757.12 | X27: =W27*0.97 -> 68634.406 | Y27: =X27*assumptions!$C$7 -> 89224.728 | Z27: =W27*0.03 -> 2122.7136 | AA27: =Z27*assumptions!$C$8 -> 3820.8845 | AB27: 979 | AC27: 3 | AD27: 12 | AE27: 3.5 | AF27: 12600 | AG27: 27579 | AH27: 96000 | AI27: 24000 | AJ27: 22500 | AK27: 7650 | AL27: 20249 | AM27: =Y27+AF27+AG27+AH27+AI27+AJ27+AK27+AL27+AA27 -> 303623.61 | AN27: 249645 | AO27: 70000 | AP27: =AN27+AO27 -> 319645
B28: 22 CPT | C28: B777-200er | D28: SAF | E28: =156*2 -> 312 | F28: =E28/2 -> 156 | G28: =E28 -> 312 | H28: =_xlfn.XLOOKUP(B28,'[1]Baseline 2025'!$B:$B,'[1]Baseline 2025'!$C:$C) -> 9652 | I28: =E28*H28 -> 3011424 | J28: =_xlfn.XLOOKUP(B28,'[1]Baseline 2025'!$B:$B,'[1]Baseline 2025'!$E:$E) -> Long Haul | K28: =_xlfn.XLOOKUP(B28,'[1]Baseline 2025'!$B:$B,'[1]Baseline 2025'!$I:$I)/100 -> 223447.66 | L28: =K28*100 -> 22344766 | M28: 3.84 | N28: =(L28*M28)/1000 -> 85803.902 | O28: =12/1000 -> 0.012 | P28: =(O28*L28)/1000 -> 268.13719 | Q28: =1.2/1000 -> 0.0012 | R28: =Q28*L28/1000 -> 26.813719 | S28: 300 | T28: =G28*S28*assumptions!$D$6 -> 79560 | U28: 20 | V28: 0.47222222 | W28: 71617.84 | X28: =W28*0.97 -> 69469.305 | Y28: =X28*assumptions!$C$7 -> 90310.096 | Z28: =W28*0.03 -> 2148.5352 | AA28: =Z28*assumptions!$C$8 -> 3867.3634 | AB28: 946 | AC28: 3 | AD28: 12 | AE28: 3.5 | AF28: 11896.5 | AG28: 27753 | AH28: 90640 | AI28: 22660 | AJ28: 21244 | AK28: 7650 | AL28: 19723 | AM28: =Y28+AF28+AG28+AH28+AI28+AJ28+AK28+AL28+AA28 -> 295743.96 | AN28: 241230 | AO28: 70000 | AP28: =AN28+AO28 -> 311230
N29: =SUM(N7:N28) -> 631234.43 | P29: =SUM(P7:P28) -> 1972.6076 | R29: =SUM(R7:R28) -> 197.26076
A31: yearly fuel ussage [tons] | D31: yearly costs | F31: yearly revenue
A32: =(E7*W7)/1000 -> 4309.5489 | D32: =E7*AM7 -> 36466189 | F32: =E7*AP7 -> 38416560
A33: =(E8*W8)/1000 -> 3085.8828 | D33: =E8*AM8 -> 28417544 | F33: =E8*AP8 -> 29931720
A34: =(E9*W9)/1000 -> 3315.6542 | D34: =E9*AM9 -> 31692481 | F34: =E9*AP9 -> 33342400
A35: =(E10*W10)/1000 -> 422.13808 | D35: =E10*AM10 -> 11979626 | F35: =E10*AP10 -> 30093700
A36: =(E11*W11)/1000 -> 1498.8574 | D36: =E11*AM11 -> 19698889 | F36: =E11*AP11 -> 30557800
A37: =(E12*W12)/1000 -> 533.01612 | D37: =E12*AM12 -> 9478594.2 | F37: =E12*AP12 -> 14814800
A38: =(E13*W13)/1000 -> 1005.9176 | D38: =E13*AM13 -> 11792514 | F38: =E13*AP13 -> 16207100
A39: =(E14*W14)/1000 -> 2631.6836 | D39: =E14*AM14 -> 20538816 | F39: =E14*AP14 -> 21621600
A40: =(E15*W15)/1000 -> 2468.7062 | D40: =E15*AM15 -> 20957866 | F40: =E15*AP15 -> 22054760
A41: =(E16*W16)/1000 -> 888.3602 | D41: =E16*AM16 -> 10494966 | F41: =E16*AP16 -> 15394925
A42: =(E17*W17)/1000 -> 1283.7807 | D42: =E17*AM17 -> 12650578 | F42: =E17*AP17 -> 15510950
A43: =(E18*W18)/1000 -> 1904.9649 | D43: =E18*AM18 -> 16691565 | F43: =E18*AP18 -> 17831450
... A53: =(E28*W28)/1000 -> 22344.766 | D53: =E28*AM28 -> 92272115 | F53: =E28*AP28 -> 97103760
...

Sheet Baseline 2050
A4: 97% Jet-A1 & 3% SAF
AC5: Crew costs | AJ5: Costs | AP5: Revenue
B6: Destination | C6: Aircraft | D6: Fuel type | E6: Frequency [per year] | F6: # retour | G6: # flights | H6: Lookup: Distance [km] | I6: Total distance travelled [km] | J6: Lookup: Flight Type | K6: Lookup: fuel consumption [l/100km] | L6: Conditional: Total fuel consumption [l] | M6: SAF LFEC CO2 per kg [kg/kg] | N6: Total CO2 emmission [kg] (tons) | O6: NOX per KG | P6: Total NOX emmision(Tons) | Q6: Sox per KG | R6: Total Sox emmission(Ton) | S6: Seats | T6: Passengers per year | U6: Available cargo (Tons) | V6: Flight time | W6: Fuel | X6: jet-A1 Fuel | Y6: Jet-A1 price | Z6: SAF fuel | AA6: SAF price | AB6: Ticket price | AC6: Pilot | AD6: Cabin crew | AE6: Freight rate (Euro/KG) | AF6: CO2 Price(KG/TON) | AG6: Crew costs | AH6: Airport & Navigation charges | AI6: Maintenance costs | AJ6: Maintenance reserve | AK6: Operational lease | AL6: catering and inflight services | AM6: Insurance and overhead | AN6: Total costs | AO6: Passenger revenu | AP6: Cargo revenu | AQ6: Total revenue
B7: 1 ALC | C7: Fokker 100 | D7: SAF | E7: =7*52*2 -> 728 | F7: =E7/2 -> 364 | G7: =E7 -> 728 | H7: =_xlfn.XLOOKUP(B7,'[1]Baseline 2025'!$B:$B,'[1]Baseline 2025'!$C:$C) -> 1613 | I7: =E7*H7 -> 1174264 | J7: =_xlfn.XLOOKUP(B7,'[1]Baseline 2025'!$B:$B,'[1]Baseline 2025'!$E:$E) -> Short Haul | K7: =_xlfn.XLOOKUP(B7,'[1]Baseline 2025'!$B:$B,'[1]Baseline 2025'!$I:$I)/100 -> 43095.489 | L7: =K7*100 -> 4309548.9 | M7: 3.84 | N7: =(L7*M7)/1000 -> 16548.668 | O7: =12/1000 -> 0.012 | P7: =(O7*L7)/1000 -> 51.714587 | Q7: =1.2/1000 -> 0.0012 | R7: =Q7*L7/1000 -> 5.1714587 | S7: 100 | T7: =G7*S7*assumptions!$D$6 -> 61880 | U7: 10.9 | V7: 0.11111111 | W7: 5919.71 | X7: =W7*0.97 -> 5742.1187 | Y7: =X7*assumptions!$C$7 -> 7464.7543 | Z7: =W7*0.03 -> 177.5913 | AA7: =Z7*assumptions!$D$8 -> 230.86869 | AB7: 172 | AC7: 2 | AD7: 3 | AE7: 3.5 | AF7: 9071 | AG7: 1197 | AH7: 6845 | AI7: 21280 | AJ7: 5320 | AK7: 1663 | AL7: 2550 | AM7: 3333 | AN7: =Y7+AG7+AH7+AI7+AJ7+AK7+AL7+AM7+AA7+AF7 -> 58954.623 | AO7: 14620 | AP7: 38150 | AQ7: =AO7+AP7 -> 52770
B8: 2 ARN | C8: Fokker 100 | D8: SAF | E8: =7*52*2 -> 728 | F8: =E8/2 -> 364 | G8: =E8 -> 728 | H8: =_xlfn.XLOOKUP(B8,'[1]Baseline 2025'!$B:$B,'[1]Baseline 2025'!$C:$C) -> 1155 | I8: =E8*H8 -> 840840 | J8: =_xlfn.XLOOKUP(B8,'[1]Baseline 2025'!$B:$B,'[1]Baseline 2025'!$E:$E) -> Short Haul | K8: =_xlfn.XLOOKUP(B8,'[1]Baseline 2025'!$B:$B,'[1]Baseline 2025'!$I:$I)/100 -> 30858.828 | L8: =K8*100 -> 3085882.8 | M8: 3.84 | N8: =(L8*M8)/1000 -> 11849.79 | O8: =12/1000 -> 0.012 | P8: =(O8*L8)/1000 -> 37.030594 | Q8: =1.2/1000 -> 0.0012 | R8: =Q8*L8/1000 -> 3.7030594 | S8: 100 | T8: =G8*S8*assumptions!$D$6 -> 61880 | U8: 10.9 | V8: 0.083333333 | W8: 4238.85 | X8: =W8*0.97 -> 4111.6845 | Y8: =X8*assumptions!$C$7 -> 5345.1899 | Z8: =W8*0.03 -> 127.1655 | AA8: =Z8*assumptions!$D$8 -> 165.31515 | AB8: 99 | AC8: 2 | AD8: 3 | AE8: 3 | AF8: 6496 | AG8: 900 | AH8: 6158 | AI8: 16000 | AJ8: 4000 | AK8: 1250 | AL8: 2550 | AM8: 2603 | AN8: =Y8+AG8+AH8+AI8+AJ8+AK8+AL8+AM8+AA8+AF8 -> 45467.505 | AO8: 8415 | AP8: 32700 | AQ8: =AO8+AP8 -> 41115
B9: 3 BCN | C9: Fokker 100 | D9: SAF | E9: =7*52*2 -> 728 | F9: =E9/2 -> 364 | G9: =E9 -> 728 | H9: =_xlfn.XLOOKUP(B9,'[1]Baseline 2025'!$B:$B,'[1]Baseline 2025'!$C:$C) -> 1241 | I9: =E9*H9 -> 903448 | J9: =_xlfn.XLOOKUP(B9,'[1]Baseline 2025'!$B:$B,'[1]Baseline 2025'!$E:$E) -> Short Haul | K9: =_xlfn.XLOOKUP(B9,'[1]Baseline 2025'!$B:$B,'[1]Baseline 2025'!$I:$I)/100 -> 33156.542 | L9: =K9*100 -> 3315654.2 | M9: 3.84 | N9: =(L9*M9)/1000 -> 12732.112 | O9: =12/1000 -> 0.012 | P9: =(O9*L9)/1000 -> 39.78785 | Q9: =1.2/1000 -> 0.0012 | R9: =Q9*L9/1000 -> 3.978785 | S9: 100 | T9: =G9*S9*assumptions!$D$6 -> 61880 | U9: 10.9 | V9: 0.097222222 | W9: 4554.47 | X9: =W9*0.97 -> 4417.8359 | Y9: =X9*assumptions!$C$7 -> 5743.1867 | Z9: =W9*0.03 -> 136.6341 | AA9: =Z9*assumptions!$D$8 -> 177.62433 | AB9: 90 | AC9: 2 | AD9: 3 | AE9: 3.5 | AF9: 6979 | AG9: 1048.5 | AH9: 6287 | AI9: 18640 | AJ9: 4660 | AK9: 1456 | AL9: 2550 | AM9: 2903 | AN9: =Y9+AG9+AH9+AI9+AJ9+AK9+AL9+AM9+AA9+AF9 -> 50444.311 | AO9: 7650 | AP9: 38150 | AQ9: =AO9+AP9 -> 45800
B10: 4 BRU | C10: Fokker 100 | D10: SAF | E10: =14*52 -> 728 | F10: =E10/2 -> 364 | G10: =E10 -> 728 | H10: =_xlfn.XLOOKUP(B10,'[1]Baseline 2025'!$B:$B,'[1]Baseline 2025'!$C:$C) -> 158 | I10: =E10*H10 -> 115024 | J10: =_xlfn.XLOOKUP(B10,'[1]Baseline 2025'!$B:$B,'[1]Baseline 2025'!$E:$E) -> Short Haul | K10: =_xlfn.XLOOKUP(B10,'[1]Baseline 2025'!$B:$B,'[1]Baseline 2025'!$I:$I)/100 -> 8442.7616 | L10: =K10*100 -> 844276.16 | M10: 3.84 | N10: =(L10*M10)/1000 -> 3242.0205 | O10: =12/1000 -> 0.012 | P10: =(O10*L10)/1000 -> 10.131314 | Q10: =1.2/1000 -> 0.0012 | R10: =Q10*L10/1000 -> 1.0131314 | S10: 100 | T10: =G10*S10*assumptions!$D$6 -> 61880 | U10: 10.9 | V10: 0.027777778 | W10: 579.86 | X10: =W10*0.97 -> 562.4642 | Y10: =X10*assumptions!$C$7 -> 731.20346 | Z10: =W10*0.03 -> 17.3958 | AA10: =Z10*assumptions!$D$8 -> 22.61454 | AB10: 37.5 | AC10: 2 | AD10: 3 | AE10: 3.5 | AF10: 888 | AG10: 300.015 | AH10: 4662 | AI10: 5333.6 | AJ10: 1333.4 | AK10: 417 | AL10: 2550 | AM10: 1097 | AN10: =Y10+AG10+AH10+AI10+AJ10+AK10+AL10+AM10+AA10+AF10 -> 17334.833 | AO10: 3187.5 | AP10: 38150 | AQ10: =AO10+AP10 -> 41337.5
B11: 5 BSL | C11: Fokker 100 | D11: SAF | E11: =7*52*2 -> 728 | F11: =E11/2 -> 364 | G11: =E11 -> 728 | H11: =_xlfn.XLOOKUP(B11,'[1]Baseline 2025'!$B:$B,'[1]Baseline 2025'!$C:$C) -> 561 | I11: =E11*H11 -> 408408 | J11: =_xlfn.XLOOKUP(B11,'[1]Baseline 2025'!$B:$B,'[1]Baseline 2025'!$E:$E) -> Short Haul | K11: =_xlfn.XLOOKUP(B11,'[1]Baseline 2025'!$B:$B,'[1]Baseline 2025'!$I:$I)/100 -> 14988.574 | L11: =K11*100 -> 1498857.4 | M11: 3.84 | N11: =(L11*M11)/1000 -> 5755.6123 | O11: =12/1000 -> 0.012 | P11: =(O11*L11)/1000 -> 17.986288 | Q11: =1.2/1000 -> 0.0012 | R11: =Q11*L11/1000 -> 1.7986288 | S11: 100 | T11: =G11*S11*assumptions!$D$6 -> 61880 | U11: 10.9 | V11: 0.055555556 | W11: 2058.87 | X11: =W11*0.97 -> 1997.1039 | Y11: =X11*assumptions!$C$7 -> 2596.2351 | Z11: =W11*0.03 -> 61.7661 | AA11: =Z11*assumptions!$D$8 -> 80.29593 | AB11: 45 | AC11: 2 | AD11: 3 | AE11: 3.5 | AF11: 3155 | AG11: 598.5 | AH11: 5267 | AI11: 10640 | AJ11: 2660 | AK11: 831 | AL11: 2550 | AM11: 1805 | AN11: =Y11+AG11+AH11+AI11+AJ11+AK11+AL11+AM11+AA11+AF11 -> 30183.031 | AO11: 3825 | AP11: 38150 | AQ11: =AO11+AP11 -> 41975
B12: 6 CDG | C12: Fokker 100 | D12: SAF | E12: =7*52 -> 364 | F12: =E12/2 -> 182 | G12: =E12 -> 364 | H12: =_xlfn.XLOOKUP(B12,'[1]Baseline 2025'!$B:$B,'[1]Baseline 2025'!$C:$C) -> 399 | I12: =E12*H12 -> 145236 | J12: =_xlfn.XLOOKUP(B12,'[1]Baseline 2025'!$B:$B,'[1]Baseline 2025'!$E:$E) -> Short Haul | K12: =_xlfn.XLOOKUP(B12,'[1]Baseline 2025'!$B:$B,'[1]Baseline 2025'!$I:$I)/100 -> 10660.322 | L12: =K12*100 -> 1066032.2 | M12: 3.84 | N12: =(L12*M12)/1000 -> 4093.5638 | O12: =12/1000 -> 0.012 | P12: =(O12*L12)/1000 -> 12.792387 | Q12: =1.2/1000 -> 0.0012 | R12: =Q12*L12/1000 -> 1.2792387 | S12: 100 | T12: =G12*S12*assumptions!$D$6 -> 30940 | U12: 10.9 | V12: 0.055555556 | W12: 1464.33 | X12: =W12*0.97 -> 1420.4001 | Y12: =X12*assumptions!$C$7 -> 1846.5201 | Z12: =W12*0.03 -> 43.9299 | AA12: =Z12*assumptions!$D$8 -> 57.10887 | AB12: 30 | AC12: 2 | AD12: 3 | AE12: 3.5 | AF12: 2243 | AG12: 598.5 | AH12: 5024 | AI12: 10640 | AJ12: 2660 | AK12: 831 | AL12: 2550 | AM12: 1811 | AN12: =Y12+AG12+AH12+AI12+AJ12+AK12+AL12+AM12+AA12+AF12 -> 28261.129 | AO12: 2550 | AP12: 38150 | AQ12: =AO12+AP12 -> 40700
B13: 7 DUB | C13: Fokker 100 | D13: SAF | E13: =7*52 -> 364 | F13: =E13/2 -> 182 | G13: =E13 -> 364 | H13: =_xlfn.XLOOKUP(B13,'[1]Baseline 2025'!$B:$B,'[1]Baseline 2025'!$C:$C) -> 753 | I13: =E13*H13 -> 274092 | J13: =_xlfn.XLOOKUP(B13,'[1]Baseline 2025'!$B:$B,'[1]Baseline 2025'!$E:$E) -> Short Haul | K13: =_xlfn.XLOOKUP(B13,'[1]Baseline 2025'!$B:$B,'[1]Baseline 2025'!$I:$I)/100 -> 20118.353 | L13: =K13*100 -> 2011835.3 | M13: 3.84 | N13: =(L13*M13)/1000 -> 7725.4475 | O13: =12/1000 -> 0.012 | P13: =(O13*L13)/1000 -> 24.142023 | Q13: =1.2/1000 -> 0.0012 | R13: =Q13*L13/1000 -> 2.4142023 | S13: 100 | T13: =G13*S13*assumptions!$D$6 -> 30940 | U13: 10.9 | V13: 0.069444444 | W13: 2763.51 | X13: =W13*0.97 -> 2680.6047 | Y13: =X13*assumptions!$C$7 -> 3484.7861 | Z13: =W13*0.03 -> 82.9053 | AA13: =Z13*assumptions!$D$8 -> 107.77689 | AB13: 75 | AC13: 2 | AD13: 3 | AE13: 3.5 | AF13: 4235 | AG13: 747 | AH13: 5555 | AI13: 13280 | AJ13: 3320 | AK13: 1038 | AL13: 2550 | AM13: 2273 | AN13: =Y13+AG13+AH13+AI13+AJ13+AK13+AL13+AM13+AA13+AF13 -> 36590.563 | AO13: 6375 | AP13: 38150 | AQ13: =AO13+AP13 -> 44525
B14: 8 FAO | C14: Fokker 100 | D14: SAF | E14: =7*52 -> 364 | F14: =E14/2 -> 182 | G14: =E14 -> 364 | H14: =_xlfn.XLOOKUP(B14,'[1]Baseline 2025'!$B:$B,'[1]Baseline 2025'!$C:$C) -> 1970 | I14: =E14*H14 -> 717080 | J14: =_xlfn.XLOOKUP(B14,'[1]Baseline 2025'!$B:$B,'[1]Baseline 2025'!$E:$E) -> Short Haul | K14: =_xlfn.XLOOKUP(B14,'[1]Baseline 2025'!$B:$B,'[1]Baseline 2025'!$I:$I)/100 -> 52633.672 | L14: =K14*100 -> 5263367.2 | M14: 3.84 | N14: =(L14*M14)/1000 -> 20211.33 | O14: =12/1000 -> 0.012 | P14: =(O14*L14)/1000 -> 63.160406 | Q14: =1.2/1000 -> 0.0012 | R14: =Q14*L14/1000 -> 6.3160406 | S14: 100 | T14: =G14*S14*assumptions!$D$6 -> 30940 | U14: 10.9 | V14: 0.125 | W14: 7229.9 | X14: =W14*0.97 -> 7013.003 | Y14: =X14*assumptions!$C$7 -> 9116.9039 | Z14: =W14*0.03 -> 216.897 | AA14: =Z14*assumptions!$D$8 -> 281.9661 | AB14: 250 | AC14: 2 | AD14: 3 | AE14: 3.5 | AF14: 11079 | AG14: 1350 | AH14: 7380 | AI14: 24000 | AJ14: 6000 | AK14: 1875 | AL14: 2550 | AM14: 3763 | AN14: =Y14+AG14+AH14+AI14+AJ14+AK14+AL14+AM14+AA14+AF14 -> 67395.87 | AO14: 21250 | AP14: 38150 | AQ14: =AO14+AP14 -> 59400
B15: 9 LIS | C15: Fokker 100 | D15: SAF | E15: =7*52 -> 364 | F15: =E15/2 -> 182 | G15: =E15 -> 364 | H15: =_xlfn.XLOOKUP(B15,'[1]Baseline 2025'!$B:$B,'[1]Baseline 2025'!$C:$C) -> 1848 | I15: =E15*H15 -> 672672 | J15: =_xlfn.XLOOKUP(B15,'[1]Baseline 2025'!$B:$B,'[1]Baseline 2025'!$E:$E) -> Short Haul | K15: =_xlfn.XLOOKUP(B15,'[1]Baseline 2025'!$B:$B,'[1]Baseline 2025'!$I:$I)/100 -> 49374.125 | L15: =K15*100 -> 4937412.5 | M15: 3.84 | N15: =(L15*M15)/1000 -> 18959.664 | O15: =12/1000 -> 0.012 | P15: =(O15*L15)/1000 -> 59.24895 | Q15: =1.2/1000 -> 0.0012 | R15: =Q15*L15/1000 -> 5.924895 | S15: 100 | T15: =G15*S15*assumptions!$D$6 -> 30940 | U15: 10.9 | V15: 0.13194444 | W15: 6782.16 | X15: =W15*0.97 -> 6578.6952 | Y15: =X15*assumptions!$C$7 -> 8552.3038 | Z15: =W15*0.03 -> 203.4648 | AA15: =Z15*assumptions!$D$8 -> 264.50424 | AB15: 264 | AC15: 2 | AD15: 3 | AE15: 3.5 | AF15: 10393 | AG15: 1425.015 | AH15: 7197 | AI15: 25333.6 | AJ15: 6333.4 | AK15: 1979 | AL15: 2550 | AM15: 3840 | AN15: =Y15+AG15+AH15+AI15+AJ15+AK15+AL15+AM15+AA15+AF15 -> 67867.823 | AO15: 22440 | AP15: 38150 | AQ15: =AO15+AP15 -> 60590
B16: 10 MUC | C16: Fokker 100 | D16: SAF | E16: =7*52 -> 364 | F16: =E16/2 -> 182 | G16: =E16 -> 364 | H16: =_xlfn.XLOOKUP(B16,'[1]Baseline 2025'!$B:$B,'[1]Baseline 2025'!$C:$C) -> 665 | I16: =E16*H16 -> 242060 | J16: =_xlfn.XLOOKUP(B16,'[1]Baseline 2025'!$B:$B,'[1]Baseline 2025'!$E:$E) -> Short Haul | K16: =_xlfn.XLOOKUP(B16,'[1]Baseline 2025'!$B:$B,'[1]Baseline 2025'!$I:$I)/100 -> 17767.204 | L16: =K16*100 -> 1776720.4 | M16: 3.84 | N16: =(L16*M16)/1000 -> 6822.6063 | O16: =12/1000 -> 0.012 | P16: =(O16*L16)/1000 -> 21.320645 | Q16: =1.2/1000 -> 0.0012 | R16: =Q16*L16/1000 -> 2.1320645 | S16: 100 | T16: =G16*S16*assumptions!$D$6 -> 30940 | U16: 10.9 | V16: 0.059027778 | W16: 2440.55 | X16: =W16*0.97 -> 2367.3335 | Y16: =X16*assumptions!$C$7 -> 3077.5335 | Z16: =W16*0.03 -> 73.2165 | AA16: =Z16*assumptions!$D$8 -> 95.18145 | AB16: 49 | AC16: 2 | AD16: 3 | AE16: 3.5 | AF16: 4855 | AG16: 639 | AH16: 5423 | AI16: 11360 | AJ16: 2840 | AK16: 888 | AL16: 2550 | AM16: 1923 | AN16: =Y16+AG16+AH16+AI16+AJ16+AK16+AL16+AM16+AA16+AF16 -> 33650.715 | AO16: 4143.75 | AP16: 38150 | AQ16: =AO16+AP16 -> 42293.75
B17: 11 OSL | C17: Fokker 100 | D17: SAF | E17: =7*52 -> 364 | F17: =E17/2 -> 182 | G17: =E17 -> 364 | H17: =_xlfn.XLOOKUP(B17,'[1]Baseline 2025'!$B:$B,'[1]Baseline 2025'!$C:$C) -> 961 | I17: =E17*H17 -> 349804 | J17: =_xlfn.XLOOKUP(B17,'[1]Baseline 2025'!$B:$B,'[1]Baseline 2025'!$E:$E) -> Short Haul | K17: =_xlfn.XLOOKUP(B17,'[1]Baseline 2025'!$B:$B,'[1]Baseline 2025'!$I:$I)/100 -> 25675.614 | L17: =K17*100 -> 2567561.4 | M17: 3.84 | N17: =(L17*M17)/1000 -> 9859.4356 | O17: =12/1000 -> 0.012 | P17: =(O17*L17)/1000 -> 30.810736 | Q17: =1.2/1000 -> 0.0012 | R17: =Q17*L17/1000 -> 3.0810736 | S17: 100 | T17: =G17*S17*assumptions!$D$6 -> 30940 | U17: 10.9 | V17: 0.072916667 | W17: 3526.87 | X17: =W17*0.97 -> 3421.0639 | Y17: =X17*assumptions!$C$7 -> 4447.3831 | Z17: =W17*0.03 -> 105.8061 | AA17: =Z17*assumptions!$D$8 -> 137.54793 | AB17: 52.5 | AC17: 2 | AD17: 3 | AE17: 3.5 | AF17: 5404 | AG17: 787.5 | AH17: 5867 | AI17: 14000 | AJ17: 3500 | AK17: 1094 | AL17: 2550 | AM17: 2318 | AN17: =Y17+AG17+AH17+AI17+AJ17+AK17+AL17+AM17+AA17+AF17 -> 40105.431 | AO17: 4462.5 | AP17: 38150 | AQ17: =AO17+AP17 -> 42612.5
B18: 12 PMI | C18: Fokker 100 | D18: SAF | E18: =7*52 -> 364 | F18: =E18/2 -> 182 | G18: =E18 -> 364 | H18: =_xlfn.XLOOKUP(B18,'[1]Baseline 2025'!$B:$B,'[1]Baseline 2025'!$C:$C) -> 1426 | I18: =E18*H18 -> 519064 | J18: =_xlfn.XLOOKUP(B18,'[1]Baseline 2025'!$B:$B,'[1]Baseline 2025'!$E:$E) -> Short Haul | K18: =_xlfn.XLOOKUP(B18,'[1]Baseline 2025'!$B:$B,'[1]Baseline 2025'!$I:$I)/100 -> 38099.298 | L18: =K18*100 -> 3809929.8 | M18: 3.84 | N18: =(L18*M18)/1000 -> 14630.13 | O18: =12/1000 -> 0.012 | P18: =(O18*L18)/1000 -> 45.719157 | Q18: =1.2/1000 -> 0.0012 | R18: =Q18*L18/1000 -> 4.5719157 | S18: 100 | T18: =G18*S18*assumptions!$D$6 -> 30940 | U18: 10.9 | V18: 0.10069444 | W18: 5233.42 | X18: =W18*0.97 -> 5076.4174 | Y18: =X18*assumptions!$C$7 -> 6599.3426 | Z18: =W18*0.03 -> 157.0026 | AA18: =Z18*assumptions!$D$8 -> 204.10338 | AB18: 128 | AC18: 2 | AD18: 3 | AE18: 3.5 | AF18: 8019 | AG18: 1089 | AH18: 6564 | AI18: 19360 | AJ18: 4840 | AK18: 1513 | AL18: 2550 | AM18: 3058 | AN18: =Y18+AG18+AH18+AI18+AJ18+AK18+AL18+AM18+AA18+AF18 -> 53796.446 | AO18: 10837.5 | AP18: 38150 | AQ18: =AO18+AP18 -> 48987.5
B19: 13 VIE | C19: Fokker 100 | D19: SAF | E19: =7*52 -> 364 | F19: =E19/2 -> 182 | G19: =E19 -> 364 | H19: =_xlfn.XLOOKUP(B19,'[1]Baseline 2025'!$B:$B,'[1]Baseline 2025'!$C:$C) -> 962 | I19: =E19*H19 -> 350168 | J19: =_xlfn.XLOOKUP(B19,'[1]Baseline 2025'!$B:$B,'[1]Baseline 2025'!$E:$E) -> Short Haul | K19: =_xlfn.XLOOKUP(B19,'[1]Baseline 2025'!$B:$B,'[1]Baseline 2025'!$I:$I)/100 -> 25702.331 | L19: =K19*100 -> 2570233.1 | M19: 3.84 | N19: =(L19*M19)/1000 -> 9869.6952 | O19: =12/1000 -> 0.012 | P19: =(O19*L19)/1000 -> 30.842797 | Q19: =1.2/1000 -> 0.0012 | R19: =Q19*L19/1000 -> 3.0842797 | S19: 100 | T19: =G19*S19*assumptions!$D$6 -> 30940 | U19: 10.9 | V19: 0.072916667 | W19: 3530.54 | X19: =W19*0.97 -> 3424.6238 | Y19: =X19*assumptions!$C$7 -> 4452.0109 | Z19: =W19*0.03 -> 105.9162 | AA19: =Z19*assumptions!$D$8 -> 137.69106 | AB19: 60.75 | AC19: 2 | AD19: 3 | AE19: 3.5 | AF19: 5411 | AG19: 787.5 | AH19: 5868 | AI19: 14000 | AJ19: 3500 | AK19: 1094 | AL19: 2550 | AM19: 2318 | AN19: =Y19+AG19+AH19+AI19+AJ19+AK19+AL19+AM19+AA19+AF19 -> 40118.202 | AO19: 5163.75 | AP19: 38150 | AQ19: =AO19+AP19 -> 43313.75
B20: 14 WAW | C20: Fokker 100 | D20: SAF | E20: =7*52 -> 364 | F20: =E20/2 -> 182 | G20: =E20 -> 364 | H20: =_xlfn.XLOOKUP(B20,'[1]Baseline 2025'!$B:$B,'[1]Baseline 2025'!$C:$C) -> 1105 | I20: =E20*H20 -> 402220 | J20: =_xlfn.XLOOKUP(B20,'[1]Baseline 2025'!$B:$B,'[1]Baseline 2025'!$E:$E) -> Short Haul | K20: =_xlfn.XLOOKUP(B20,'[1]Baseline 2025'!$B:$B,'[1]Baseline 2025'!$I:$I)/100 -> 29522.948 | L20: =K20*100 -> 2952294.8 | M20: 3.84 | N20: =(L20*M20)/1000 -> 11336.812 | O20: =12/1000 -> 0.012 | P20: =(O20*L20)/1000 -> 35.427538 | Q20: =1.2/1000 -> 0.0012 | R20: =Q20*L20/1000 -> 3.5427538 | S20: 100 | T20: =G20*S20*assumptions!$D$6 -> 30940 | U20: 10.9 | V20: 0.079861111 | W20: 4055.35 | X20: =W20*0.97 -> 3933.6895 | Y20: =X20*assumptions!$C$7 -> 5113.7964 | Z20: =W20*0.03 -> 121.6605 | AA20: =Z20*assumptions!$D$8 -> 158.15865 | AB20: 66 | AC20: 2 | AD20: 3 | AE20: 3.5 | AF20: 6559 | AG20: 862.515 | AH20: 6083 | AI20: 15333.6 | AJ20: 3833.4 | AK20: 1198 | AL20: 2550 | AM20: 2515 | AN20: =Y20+AG20+AH20+AI20+AJ20+AK20+AL20+AM20+AA20+AF20 -> 44206.47 | AO20: 5610 | AP20: 38150 | AQ20: =AO20+AP20 -> 43760
B21: 15 ZRH | C21: Fokker 100 | D21: SAF | E21: =14*52*2 -> 1456 | F21: =E21/2 -> 728 | G21: =E21 -> 1456 | H21: =_xlfn.XLOOKUP(B21,'[1]Baseline 2025'!$B:$B,'[1]Baseline 2025'!$C:$C) -> 603 | I21: =E21*H21 -> 877968 | J21: =_xlfn.XLOOKUP(B21,'[1]Baseline 2025'!$B:$B,'[1]Baseline 2025'!$E:$E) -> Short Haul | K21: =_xlfn.XLOOKUP(B21,'[1]Baseline 2025'!$B:$B,'[1]Baseline 2025'!$I:$I)/100 -> 32221.426 | L21: =K21*100 -> 3222142.6 | M21: 3.84 | N21: =(L21*M21)/1000 -> 12373.027 | O21: =12/1000 -> 0.012 | P21: =(O21*L21)/1000 -> 38.665711 | Q21: =1.2/1000 -> 0.0012 | R21: =Q21*L21/1000 -> 3.8665711 | S21: 100 | T21: =G21*S21*assumptions!$D$6 -> 123760 | U21: 10.9 | V21: 0.059027778 | W21: 2213.01 | X21: =W21*0.97 -> 2146.6197 | Y21: =X21*assumptions!$C$7 -> 2790.6056 | Z21: =W21*0.03 -> 66.3903 | AA21: =Z21*assumptions!$D$8 -> 86.30739 | AB21: 48.75 | AC21: 2 | AD21: 3 | AE21: 3.5 | AF21: 3392 | AG21: 637.515 | AH21: 5330 | AI21: 11333.6 | AJ21: 2833.4 | AK21: 885 | AL21: 2550 | AM21: 1892 | AN21: =Y21+AG21+AH21+AI21+AJ21+AK21+AL21+AM21+AA21+AF21 -> 31730.428 | AO21: 4143.75 | AP21: 38150 | AQ21: =AO21+AP21 -> 42293.75
B22: 16 BKK | C22: B777-200er | D22: SAF | E22: =3*52*2 -> 312 | F22: =E22/2 -> 156 | G22: =E22 -> 312 | H22: =_xlfn.XLOOKUP(B22,'[1]Baseline 2025'!$B:$B,'[1]Baseline 2025'!$C:$C) -> 9217 | I22: =E22*H22 -> 2875704 | J22: =_xlfn.XLOOKUP(B22,'[1]Baseline 2025'!$B:$B,'[1]Baseline 2025'!$E:$E) -> Long Haul | K22: =_xlfn.XLOOKUP(B22,'[1]Baseline 2025'!$B:$B,'[1]Baseline 2025'!$I:$I)/100 -> 213377.24 | L22: =K22*100 -> 21337724 | M22: 3.84 | N22: =(L22*M22)/1000 -> 81936.859 | O22: =12/1000 -> 0.012 | P22: =(O22*L22)/1000 -> 256.05268 | Q22: =1.2/1000 -> 0.0012 | R22: =Q22*L22/1000 -> 25.605268 | S22: 300 | T22: =G22*S22*assumptions!$D$6 -> 79560 | U22: 20 | V22: 0.46875 | W22: 68390.14 | X22: =W22*0.97 -> 66338.436 | Y22: =X22*assumptions!$C$7 -> 86239.967 | Z22: =W22*0.03 -> 2051.7042 | AA22: =Z22*assumptions!$D$8 -> 2667.2155 | AB22: 920 | AC22: 3 | AD22: 12 | AE22: 3.5 | AF22: 104795 | AG22: 11812.5 | AH22: 27101 | AI22: 90000 | AJ22: 22500 | AK22: 21094 | AL22: 7650 | AM22: 19300 | AN22: =Y22+AG22+AH22+AI22+AJ22+AK22+AL22+AM22+AA22+AF22 -> 393159.68 | AO22: 234600 | AP22: 70000 | AQ22: =AO22+AP22 -> 304600
B23: 17 MFM | C23: B777-200er | D23: SAF | E23: =3*52*2 -> 312 | F23: =E23/2 -> 156 | G23: =E23 -> 312 | H23: =_xlfn.XLOOKUP(B23,'[1]Baseline 2025'!$B:$B,'[1]Baseline 2025'!$C:$C) -> 9285 | I23: =E23*H23 -> 2896920 | J23: =_xlfn.XLOOKUP(B23,'[1]Baseline 2025'!$B:$B,'[1]Baseline 2025'!$E:$E) -> Long Haul | K23: =_xlfn.XLOOKUP(B23,'[1]Baseline 2025'!$B:$B,'[1]Baseline 2025'!$I:$I)/100 -> 214951.46 | L23: =K23*100 -> 21495146 | M23: 3.84 | N23: =(L23*M23)/1000 -> 82541.362 | O23: =12/1000 -> 0.012 | P23: =(O23*L23)/1000 -> 257.94176 | Q23: =1.2/1000 -> 0.0012 | R23: =Q23*L23/1000 -> 25.794176 | S23: 300 | T23: =G23*S23*assumptions!$D$6 -> 79560 | U23: 20 | V23: 0.46875 | W23: 68894.7 | X23: =W23*0.97 -> 66827.859 | Y23: =X23*assumptions!$C$7 -> 86876.217 | Z23: =W23*0.03 -> 2066.841 | AA23: =Z23*assumptions!$D$8 -> 2686.8933 | AB23: 924 | AC23: 3 | AD23: 12 | AE23: 3.5 | AF23: 105569 | AG23: 11812.5 | AH23: 27203 | AI23: 90000 | AJ23: 22500 | AK23: 21094 | AL23: 7650 | AM23: 19354 | AN23: =Y23+AG23+AH23+AI23+AJ23+AK23+AL23+AM23+AA23+AF23 -> 394745.61 | AO23: 235620 | AP23: 70000 | AQ23: =AO23+AP23 -> 305620
B24: 18 HAN | C24: B777-200er | D24: SAF | E24: =52*2 -> 104 | F24: =E24/2 -> 52 | G24: =E24 -> 104 | H24: =_xlfn.XLOOKUP(B24,'[1]Baseline 2025'!$B:$B,'[1]Baseline 2025'!$C:$C) -> 8886 | I24: =E24*H24 -> 924144 | J24: =_xlfn.XLOOKUP(B24,'[1]Baseline 2025'!$B:$B,'[1]Baseline 2025'!$E:$E) -> Long Haul | K24: =_xlfn.XLOOKUP(B24,'[1]Baseline 2025'!$B:$B,'[1]Baseline 2025'!$I:$I)/100 -> 68571.485 | L24: =K24*100 -> 6857148.5 | M24: 3.84 | N24: =(L24*M24)/1000 -> 26331.45 | O24: =12/1000 -> 0.012 | P24: =(O24*L24)/1000 -> 82.285782 | Q24: =1.2/1000 -> 0.0012 | R24: =Q24*L24/1000 -> 8.2285782 | S24: 300 | T24: =G24*S24*assumptions!$D$6 -> 26520 | U24: 20 | V24: 0.45833333 | W24: 65934.12 | X24: =W24*0.97 -> 63956.096 | Y24: =X24*assumptions!$C$7 -> 83142.925 | Z24: =W24*0.03 -> 1978.0236 | AA24: =Z24*assumptions!$D$8 -> 2571.4307 | AB24: 889 | AC24: 3 | AD24: 12 | AE24: 3.5 | AF24: 101032 | AG24: 11550 | AH24: 26604 | AI24: 88000 | AJ24: 22000 | AK24: 20625 | AL24: 7650 | AM24: 18802 | AN24: =Y24+AG24+AH24+AI24+AJ24+AK24+AL24+AM24+AA24+AF24 -> 381977.36 | AO24: 226695 | AP24: 70000 | AQ24: =AO24+AP24 -> 296695
B25: 19 PTY | C25: B777-200er | D25: SAF | E25: =156*2 -> 312 | F25: =E25/2 -> 156 | G25: =E25 -> 312 | H25: =_xlfn.XLOOKUP(B25,'[1]Baseline 2025'!$B:$B,'[1]Baseline 2025'!$C:$C) -> 8818 | I25: =E25*H25 -> 2751216 | J25: =_xlfn.XLOOKUP(B25,'[1]Baseline 2025'!$B:$B,'[1]Baseline 2025'!$E:$E) -> Long Haul | K25: =_xlfn.XLOOKUP(B25,'[1]Baseline 2025'!$B:$B,'[1]Baseline 2025'!$I:$I)/100 -> 204140.23 | L25: =K25*100 -> 20414023 | M25: 3.84 | N25: =(L25*M25)/1000 -> 78389.847 | O25: =12/1000 -> 0.012 | P25: =(O25*L25)/1000 -> 244.96827 | Q25: =1.2/1000 -> 0.0012 | R25: =Q25*L25/1000 -> 24.496827 | S25: 300 | T25: =G25*S25*assumptions!$D$6 -> 79560 | U25: 20 | V25: 0.46527778 | W25: 65429.56 | X25: =W25*0.97 -> 63466.673 | Y25: =X25*assumptions!$C$7 -> 82506.675 | Z25: =W25*0.03 -> 1962.8868 | AA25: =Z25*assumptions!$D$8 -> 2551.7528 | AB25: 896 | AC25: 3 | AD25: 12 | AE25: 3.5 | AF25: 100260 | AG25: 11718 | AH25: 26502 | AI25: 89280 | AJ25: 22320 | AK25: 20925 | AL25: 7650 | AM25: 18895 | AN25: =Y25+AG25+AH25+AI25+AJ25+AK25+AL25+AM25+AA25+AF25 -> 382608.43 | AO25: 228480 | AP25: 70000 | AQ25: =AO25+AP25 -> 298480
B26: 20 MEX | C26: B777-200er | D26: SAF | E26: =156*2 -> 312 | F26: =E26/2 -> 156 | G26: =E26 -> 312 | H26: =_xlfn.XLOOKUP(B26,'[1]Baseline 2025'!$B:$B,'[1]Baseline 2025'!$C:$C) -> 9220 | I26: =E26*H26 -> 2876640 | J26: =_xlfn.XLOOKUP(B26,'[1]Baseline 2025'!$B:$B,'[1]Baseline 2025'!$E:$E) -> Long Haul | K26: =_xlfn.XLOOKUP(B26,'[1]Baseline 2025'!$B:$B,'[1]Baseline 2025'!$I:$I)/100 -> 213446.69 | L26: =K26*100 -> 21344669 | M26: 3.84 | N26: =(L26*M26)/1000 -> 81963.528 | O26: =12/1000 -> 0.012 | P26: =(O26*L26)/1000 -> 256.13603 | Q26: =1.2/1000 -> 0.0012 | R26: =Q26*L26/1000 -> 25.613603 | S26: 300 | T26: =G26*S26*assumptions!$D$6 -> 79560 | U26: 20 | V26: 0.47916667 | W26: 68412.4 | X26: =W26*0.97 -> 66360.028 | Y26: =X26*assumptions!$C$7 -> 86268.036 | Z26: =W26*0.03 -> 2052.372 | AA26: =Z26*assumptions!$D$8 -> 2668.0836 | AB26: 935 | AC26: 3 | AD26: 12 | AE26: 3.5 | AF26: 104830 | AG26: 12075 | AH26: 27105 | AI26: 92000 | AJ26: 23000 | AK26: 21563 | AL26: 7650 | AM26: 19533 | AN26: =Y26+AG26+AH26+AI26+AJ26+AK26+AL26+AM26+AA26+AF26 -> 396692.12 | AO26: 238425 | AP26: 70000 | AQ26: =AO26+AP26 -> 308425
B27: 21 GIG | C27: B777-200er | D27: SAF | E27: =52*2 -> 104 | F27: =E27/2 -> 52 | G27: =E27 -> 104 | H27: =_xlfn.XLOOKUP(B27,'[1]Baseline 2025'!$B:$B,'[1]Baseline 2025'!$C:$C) -> 9536 | I27: =E27*H27 -> 991744 | J27: =_xlfn.XLOOKUP(B27,'[1]Baseline 2025'!$B:$B,'[1]Baseline 2025'!$E:$E) -> Long Haul | K27: =_xlfn.XLOOKUP(B27,'[1]Baseline 2025'!$B:$B,'[1]Baseline 2025'!$I:$I)/100 -> 73587.405 | L27: =K27*100 -> 7358740.5 | M27: 3.84 | N27: =(L27*M27)/1000 -> 28257.563 | O27: =12/1000 -> 0.012 | P27: =(O27*L27)/1000 -> 88.304886 | Q27: =1.2/1000 -> 0.0012 | R27: =Q27*L27/1000 -> 8.8304886 | S27: 300 | T27: =G27*S27*assumptions!$D$6 -> 26520 | U27: 20 | V27: 0.5 | W27: 70757.12 | X27: =W27*0.97 -> 68634.406 | Y27: =X27*assumptions!$C$7 -> 89224.728 | Z27: =W27*0.03 -> 2122.7136 | AA27: =Z27*assumptions!$D$8 -> 2759.5277 | AB27: 979 | AC27: 3 | AD27: 12 | AE27: 3.5 | AF27: 108422 | AG27: 12600 | AH27: 27579 | AI27: 96000 | AJ27: 24000 | AK27: 22500 | AL27: 7650 | AM27: 20249 | AN27: =Y27+AG27+AH27+AI27+AJ27+AK27+AL27+AM27+AA27+AF27 -> 410984.26 | AO27: 249645 | AP27: 70000 | AQ27: =AO27+AP27 -> 319645
B28: 22 CPT | C28: B777-200er | D28: SAF | E28: =156*2 -> 312 | F28: =E28/2 -> 156 | G28: =E28 -> 312 | H28: =_xlfn.XLOOKUP(B28,'[1]Baseline 2025'!$B:$B,'[1]Baseline 2025'!$C:$C) -> 9652 | I28: =E28*H28 -> 3011424 | J28: =_xlfn.XLOOKUP(B28,'[1]Baseline 2025'!$B:$B,'[1]Baseline 2025'!$E:$E) -> Long Haul | K28: =_xlfn.XLOOKUP(B28,'[1]Baseline 2025'!$B:$B,'[1]Baseline 2025'!$I:$I)/100 -> 223447.66 | L28: =K28*100 -> 22344766 | M28: 3.84 | N28: =(L28*M28)/1000 -> 85803.902 | O28: =12/1000 -> 0.012 | P28: =(O28*L28)/1000 -> 268.13719 | Q28: =1.2/1000 -> 0.0012 | R28: =Q28*L28/1000 -> 26.813719 | S28: 300 | T28: =G28*S28*assumptions!$D$6 -> 79560 | U28: 20 | V28: 0.47222222 | W28: 71617.84 | X28: =W28*0.97 -> 69469.305 | Y28: =X28*assumptions!$C$7 -> 90310.096 | Z28: =W28*0.03 -> 2148.5352 | AA28: =Z28*assumptions!$D$8 -> 2793.0958 | AB28: 946 | AC28: 3 | AD28: 12 | AE28: 3.5 | AF28: 109741 | AG28: 11896.5 | AH28: 27753 | AI28: 90640 | AJ28: 22660 | AK28: 21244 | AL28: 7650 | AM28: 19723 | AN28: =Y28+AG28+AH28+AI28+AJ28+AK28+AL28+AM28+AA28+AF28 -> 404410.69 | AO28: 241230 | AP28: 70000 | AQ28: =AO28+AP28 -> 311230
N29: =SUM(N7:N28) -> 631234.43 | P29: =SUM(P7:P28) -> 1972.6076 | R29: =SUM(R7:R28) -> 197.26076
A31: yearly fuel ussage [tons] | D31: yearly costs | F31: yearly revenue
A32: =(E7*W7)/1000 -> 4309.5489 | D32: =E7*AN7 -> 42918966 | F32: =E7*AQ7 -> 38416560
A33: =(E8*W8)/1000 -> 3085.8828 | D33: =E8*AN8 -> 33100344 | F33: =E8*AQ8 -> 29931720
A34: =(E9*W9)/1000 -> 3315.6542 | D34: =E9*AN9 -> 36723458 | F34: =E9*AQ9 -> 33342400
A35: =(E10*W10)/1000 -> 422.13808 | D35: =E10*AN10 -> 12619758 | F35: =E10*AQ10 -> 30093700
A36: =(E11*W11)/1000 -> 1498.8574 | D36: =E11*AN11 -> 21973247 | F36: =E11*AQ11 -> 30557800
A37: =(E12*W12)/1000 -> 533.01612 | D37: =E12*AN12 -> 10287051 | F37: =E12*AQ12 -> 14814800
A38: =(E13*W13)/1000 -> 1005.9176 | D38: =E13*AN13 -> 13318965 | F38: =E13*AQ13 -> 16207100
A39: =(E14*W14)/1000 -> 2631.6836 | D39: =E14*AN14 -> 24532097 | F39: =E14*AQ14 -> 21621600
A40: =(E15*W15)/1000 -> 2468.7062 | D40: =E15*AN15 -> 24703888 | F40: =E15*AQ15 -> 22054760
A41: =(E16*W16)/1000 -> 888.3602 | D41: =E16*AN16 -> 12248860 | F41: =E16*AQ16 -> 15394925
A42: =(E17*W17)/1000 -> 1283.7807 | D42: =E17*AN17 -> 14598377 | F42: =E17*AQ17 -> 15510950
A43: =(E18*W18)/1000 -> 1904.9649 | D43: =E18*AN18 -> 19581906 | F43: =E18*AQ18 -> 17831450
... A53: =(E28*W28)/1000 -> 22344.766 | D53: =E28*AN28 -> 1.2617614e+08 | F53: =E28*AQ28 -> 97103760
...

Sheet Scenario 1 2025
A4: 100% SAF
Y5: Crew costs | AF5: Costs | AL5: Revenu
B6: Destination | C6: Aircraft | D6: Fuel type | E6: Frequency [per year] | F6: # retour | G6: # flights | H6: Lookup: Distance [km] | I6: Total distance travelled [km] | J6: Lookup: Flight Type | K6: Lookup: fuel consumption [l/100km] | L6: Conditional: Total fuel consumption [l] | M6: SAF LFEC CO2 per kg [kg/kg] | N6: Total CO2 emmission [kg] (tons) | O6: NOX per KG | P6: Total NOX emmision(Tons) | Q6: Sox per KG | R6: Total Sox emmission(Ton) | S6: Seats | T6: Passengers per year | U6: Available cargo (Tons) | V6: Flight time | W6: Fuel | X6: HEFA | Y6: Pilot | Z6: Cabin crew | AA6: Ticket price | AB6: Freight rate (Euro/KG) | AC6: Crew costs | AD6: Airport & Navigation charges | AE6: Maintenance costs | AF6: Maintenance reserve | AG6: Operational lease | AH6: catering and inflight services | AI6: Insurance and overhead | AJ6: Total costs | AK6: Passenger revenue | AL6: Cargo revenue | AM6: Total revenuee | AN6: marge
B7: 1 ALC | C7: Fokker 100 | D7: SAF | E7: =7*52*2 -> 728 | F7: =E7/2 -> 364 | G7: =E7 -> 728 | H7: =_xlfn.XLOOKUP(B7,'[1]Baseline 2025'!$B:$B,'[1]Baseline 2025'!$C:$C) -> 1613 | I7: =E7*H7 -> 1174264 | J7: =_xlfn.XLOOKUP(B7,'[1]Baseline 2025'!$B:$B,'[1]Baseline 2025'!$E:$E) -> Short Haul | K7: =_xlfn.XLOOKUP(B7,'[1]Baseline 2025'!$B:$B,'[1]Baseline 2025'!$I:$I)/100 -> 43095.489 | L7: =K7*100 -> 4309548.9 | M7: =1.3 -> 1.3 | N7: =(L7*M7)/1000 -> 5602.4135 | O7: =9/1000 -> 0.009 | P7: =(O7*L7)/1000 -> 38.78594 | Q7: =0.03/1000 -> 3e-05 | R7: =Q7*L7/1000 -> 0.12928647 | S7: 100 | T7: =G7*S7*assumptions!$D$6 -> 61880 | U7: 10.9 | V7: 0.11111111 | W7: 5919.71 | X7: =W7*assumptions!$C$8 -> 10655.478 | Y7: 2 | Z7: 3 | AA7: 210 | AB7: 3.5 | AC7: 1201.5 | AD7: 6845 | AE7: 21360 | AF7: 5340 | AG7: 1669 | AH7: 2550 | AI7: 3546 | AJ7: =X7+AC7+AD7+AE7+AF7+AG7+AH7+AI7 -> 53166.978 | AK7: 17850 | AL7: 38150 | AM7: =AK7+AL7 -> 56000 | AN7: =(AM7/AJ7)-1 -> 0.053285368
B8: 2 ARN | C8: Fokker 100 | D8: SAF | E8: =7*52*2 -> 728 | F8: =E8/2 -> 364 | G8: =E8 -> 728 | H8: =_xlfn.XLOOKUP(B8,'[1]Baseline 2025'!$B:$B,'[1]Baseline 2025'!$C:$C) -> 1155 | I8: =E8*H8 -> 840840 | J8: =_xlfn.XLOOKUP(B8,'[1]Baseline 2025'!$B:$B,'[1]Baseline 2025'!$E:$E) -> Short Haul | K8: =_xlfn.XLOOKUP(B8,'[1]Baseline 2025'!$B:$B,'[1]Baseline 2025'!$I:$I)/100 -> 30858.828 | L8: =K8*100 -> 3085882.8 | M8: =1.3 -> 1.3 | N8: =(L8*M8)/1000 -> 4011.6476 | O8: =9/1000 -> 0.009 | P8: =(O8*L8)/1000 -> 27.772945 | Q8: =0.03/1000 -> 3e-05 | R8: =Q8*L8/1000 -> 0.092576484 | S8: 100 | T8: =G8*S8*assumptions!$D$6 -> 61880 | U8: 10.9 | V8: 0.083333333 | W8: 4238.85 | X8: =W8*assumptions!$C$8 -> 7629.93 | Y8: 2 | Z8: 3 | AA8: 126 | AB8: 3 | AC8: 900 | AD8: 6150 | AE8: 16000 | AF8: 4000 | AG8: 1250 | AH8: 2550 | AI8: 2750 | AJ8: =X8+AC8+AD8+AE8+AF8+AG8+AH8+AI8 -> 41229.93 | AK8: 10710 | AL8: 32700 | AM8: =AK8+AL8 -> 43410 | AN8: =(AM8/AJ8)-1 -> 0.052875908
B9: 3 BCN | C9: Fokker 100 | D9: SAF | E9: =7*52*2 -> 728 | F9: =E9/2 -> 364 | G9: =E9 -> 728 | H9: =_xlfn.XLOOKUP(B9,'[1]Baseline 2025'!$B:$B,'[1]Baseline 2025'!$C:$C) -> 1241 | I9: =E9*H9 -> 903448 | J9: =_xlfn.XLOOKUP(B9,'[1]Baseline 2025'!$B:$B,'[1]Baseline 2025'!$E:$E) -> Short Haul | K9: =_xlfn.XLOOKUP(B9,'[1]Baseline 2025'!$B:$B,'[1]Baseline 2025'!$I:$I)/100 -> 33156.542 | L9: =K9*100 -> 3315654.2 | M9: =1.3 -> 1.3 | N9: =(L9*M9)/1000 -> 4310.3504 | O9: =9/1000 -> 0.009 | P9: =(O9*L9)/1000 -> 29.840887 | Q9: =0.03/1000 -> 3e-05 | R9: =Q9*L9/1000 -> 0.099469625 | S9: 100 | T9: =G9*S9*assumptions!$D$6 -> 61880 | U9: 10.9 | V9: 0.097222222 | W9: 4554.47 | X9: =W9*assumptions!$C$8 -> 8198.046 | Y9: 2 | Z9: 3 | AA9: 120 | AB9: 3.5 | AC9: 1048.5 | AD9: 6287 | AE9: 18640 | AF9: 4660 | AG9: 1456 | AH9: 2550 | AI9: 3061 | AJ9: =X9+AC9+AD9+AE9+AF9+AG9+AH9+AI9 -> 45900.546 | AK9: 10200 | AL9: 38150 | AM9: =AK9+AL9 -> 48350 | AN9: =(AM9/AJ9)-1 -> 0.053364376
B10: 4 BRU | C10: Fokker 100 | D10: SAF | E10: =14*52 -> 728 | F10: =E10/2 -> 364 | G10: =E10 -> 728 | H10: =_xlfn.XLOOKUP(B10,'[1]Baseline 2025'!$B:$B,'[1]Baseline 2025'!$C:$C) -> 158 | I10: =E10*H10 -> 115024 | J10: =_xlfn.XLOOKUP(B10,'[1]Baseline 2025'!$B:$B,'[1]Baseline 2025'!$E:$E) -> Short Haul | K10: =_xlfn.XLOOKUP(B10,'[1]Baseline 2025'!$B:$B,'[1]Baseline 2025'!$I:$I)/100 -> 8442.7616 | L10: =K10*100 -> 844276.16 | M10: =1.3 -> 1.3 | N10: =(L10*M10)/1000 -> 1097.559 | O10: =9/1000 -> 0.009 | P10: =(O10*L10)/1000 -> 7.5984854 | Q10: =0.03/1000 -> 3e-05 | R10: =Q10*L10/1000 -> 0.025328285 | S10: 100 | T10: =G10*S10*assumptions!$D$6 -> 61880 | U10: 10.9 | V10: 0.027777778 | W10: 579.86 | X10: =W10*assumptions!$C$8 -> 1043.748 | Y10: 2 | Z10: 3 | AA10: 50 | AB10: 3.5 | AC10: 297 | AD10: 4662 | AE10: 5280 | AF10: 1320 | AG10: 413 | AH10: 2550 | AI10: 1112 | AJ10: =X10+AC10+AD10+AE10+AF10+AG10+AH10+AI10 -> 16677.748 | AK10: 4250 | AL10: 38150 | AM10: =AK10+AL10 -> 42400 | AN10: 0.607
B11: 5 BSL | C11: Fokker 100 | D11: SAF | E11: =7*52*2 -> 728 | F11: =E11/2 -> 364 | G11: =E11 -> 728 | H11: =_xlfn.XLOOKUP(B11,'[1]Baseline 2025'!$B:$B,'[1]Baseline 2025'!$C:$C) -> 561 | I11: =E11*H11 -> 408408 | J11: =_xlfn.XLOOKUP(B11,'[1]Baseline 2025'!$B:$B,'[1]Baseline 2025'!$E:$E) -> Short Haul | K11: =_xlfn.XLOOKUP(B11,'[1]Baseline 2025'!$B:$B,'[1]Baseline 2025'!$I:$I)/100 -> 14988.574 | L11: =K11*100 -> 1498857.4 | M11: =1.3 -> 1.3 | N11: =(L11*M11)/1000 -> 1948.5146 | O11: =9/1000 -> 0.009 | P11: =(O11*L11)/1000 -> 13.489716 | Q11: =0.03/1000 -> 3e-05 | R11: =Q11*L11/1000 -> 0.044965721 | S11: 100 | T11: =G11*S11*assumptions!$D$6 -> 61880 | U11: 10.9 | V11: 0.055555556 | W11: 2058.87 | X11: =W11*assumptions!$C$8 -> 3705.966 | Y11: 2 | Z11: 3 | AA11: 60 | AB11: 3.5 | AC11: 598.5 | AD11: 5267 | AE11: 10640 | AF11: 2660 | AG11: 831 | AH11: 2550 | AI11: 1876 | AJ11: =X11+AC11+AD11+AE11+AF11+AG11+AH11+AI11 -> 28128.466 | AK11: 5100 | AL11: 38150 | AM11: =AK11+AL11 -> 43250 | AN11: =(AM11/AJ11)-1 -> 0.53758829
